<?xml version="1.0" encoding="utf-8"?>
<robot name="engineer">

  <link name="base_link">
    <inertial>
      <origin xyz="0.00030037 1.9092E-05 0.047222" rpy="0 0 0" />
      <mass value="0.69152" />
      <inertia ixx="0.00080599" ixy="-3.5231E-09" ixz="-4.3565E-08" iyy="0.00052506" iyz="-1.1744E-08" izz="0.00121" />
    </inertial>
    <visual>
      <origin xyz="0 0 0" rpy="0 0 0" />
      <geometry>
        <mesh filename="package://rm_description/meshes/base_link.STL" />
      </geometry>
      <material name="">
        <color rgba="0.86667 0.9098 1 1" />
      </material>
    </visual>
    <collision>
      <origin xyz="0 0 0" rpy="0 0 0" />
      <geometry>
        <mesh filename="package://rm_description/meshes/base_link.STL" />
      </geometry>
    </collision>
  </link>

  <link name="link_1">
    <inertial>
      <origin xyz="9.3842E-05 0.04132 -0.01345" rpy="0 0 0" />
      <mass value="0.45604" />
      <inertia ixx="0.00047426" ixy="4.8904E-09" ixz="-2.522E-08" iyy="0.00088038" iyz="8.5229E-09" izz="0.00054714" />
    </inertial>
    <visual>
      <origin xyz="0 0 0" rpy="0 0 0" />
      <geometry>
        <mesh filename="package://rm_description/meshes/link_1.STL" />
      </geometry>
      <material name="">
        <color rgba="0.79216 0.81961 0.93333 1" />
      </material>
    </visual>
    <collision>
      <origin xyz="0 0 0" rpy="0 0 0" />
      <geometry>
        <mesh filename="package://rm_description/meshes/link_1.STL" />
      </geometry>
    </collision>
  </link>

  <joint name="Joint_1" type="revolute">
    <origin xyz="0 0 0.1537" rpy="0 0 0" />
    <parent link="base_link" />
    <child link="link_1" />
    <axis xyz="0 0 -1" />
    <limit lower="-3.14" upper="3.14" effort="20" velocity="3.14" />
  </joint>

  <link name="link_2">
    <inertial>
      <origin xyz="-9.1476E-12 -0.16105 0.022952" rpy="0 0 0" />
      <mass value="0.46831" />
      <inertia ixx="0.0015771" ixy="-1.5472E-12" ixz="9.6087E-12" iyy="0.00024772" iyz="-1.4099E-06" izz="0.0017042" />
    </inertial>
    <visual>
      <origin xyz="0 0 0" rpy="0 0 0" />
      <geometry>
        <mesh filename="package://rm_description/meshes/link_2.STL" />
      </geometry>
      <material name="">
        <color rgba="0.86667 0.9098 1 1" />
      </material>
    </visual>
    <collision>
      <origin xyz="0 0 0" rpy="0 0 0" />
      <geometry>
        <mesh filename="package://rm_description/meshes/link_2.STL" />
      </geometry>
    </collision>
  </link>

  <joint name="Joint_2" type="revolute">
    <origin xyz="0 0 0" rpy="-1.5708 -1.07 0" />
    <parent link="link_1" />
    <child link="link_2" />
    <axis xyz="0 0 -1" />
    <limit lower="-3.14" upper="3.14" effort="40" velocity="3.14" />
  </joint>

  <link name="link_3">
    <inertial>
      <origin xyz="-0.0086386 0.052282 0.0060748" rpy="0 0 0" />
      <mass value="0.86383" />
      <inertia ixx="0.0010242" ixy="9.2316E-05" ixz="-9.3667E-07" iyy="0.00063197" iyz="-2.0009E-06" izz="0.0010338" />
    </inertial>
    <visual>
      <origin xyz="0 0 0" rpy="0 0 0" />
      <geometry>
        <mesh filename="package://rm_description/meshes/link_3.STL" />
      </geometry>
      <material name="">
        <color rgba="0.75294 0.75294 0.75294 1" />
      </material>
    </visual>
    <collision>
      <origin xyz="0 0 0" rpy="0 0 0" />
      <geometry>
        <mesh filename="package://rm_description/meshes/link_3.STL" />
      </geometry>
    </collision>
  </link>

  <joint name="Joint_3" type="revolute">
    <origin xyz="0 -0.295 -0.05765" rpy="0 0 -0.55" />
    <parent link="link_2" />
    <child link="link_3" />
    <axis xyz="0 0 1" />
    <limit lower="-3.14" upper="3.14" effort="30" velocity="3.14" />
  </joint>

  <link name="link_4">
    <inertial>
      <origin xyz="0.00031203 0.0049107 -0.080078" rpy="0 0 0" />
      <mass value="0.35626" />
      <inertia ixx="0.00023409" ixy="-2.327E-12" ixz="9.1544E-09" iyy="0.00027599" iyz="-4.4166E-09" izz="0.00014292" />
    </inertial>
    <visual>
      <origin xyz="0 0 0" rpy="0 0 0" />
      <geometry>
        <mesh filename="package://rm_description/meshes/link_4.STL" />
      </geometry>
      <material name="">
        <color rgba="0.86667 0.9098 1 1" />
      </material>
    </visual>
    <collision>
      <origin xyz="0 0 0" rpy="0 0 0" />
      <geometry>
        <mesh filename="package://rm_description/meshes/link_4.STL" />
      </geometry>
    </collision>
  </link>

  <joint name="Joint_4" type="continuous">
    <origin xyz="-0.0245 0.27098 0" rpy="-1.5708 0 0" />
    <parent link="link_3" />
    <child link="link_4" />
    <axis xyz="0 0 -1" />
    <limit lower="-3.14" upper="3.14" effort="3" velocity="3.14" />
  </joint>

  <link name="link_5">
    <inertial>
      <origin xyz="-7.1873E-05 0.0032566 3.0102E-05" rpy="0 0 0" />
      <mass value="0.10486" />
      <inertia ixx="4.2308E-05" ixy="2.4033E-08" ixz="-6.701E-10" iyy="5.8686E-05" iyz="-4.3159E-09" izz="3.571E-05" />
    </inertial>
    <visual>
      <origin xyz="0 0 0" rpy="0 0 0" />
      <geometry>
        <mesh filename="package://rm_description/meshes/link_5.STL" />
      </geometry>
      <material name="">
        <color rgba="0.79216 0.81961 0.93333 1" />
      </material>
    </visual>
    <collision>
      <origin xyz="0 0 0" rpy="0 0 0" />
      <geometry>
        <mesh filename="package://rm_description/meshes/link_5.STL" />
      </geometry>
    </collision>
  </link>

  <joint name="Joint_5" type="revolute">
    <origin xyz="0 0 0" rpy="1.5708 0 0" />
    <parent link="link_4" />
    <child link="link_5" />
    <axis xyz="0 0 -1" />
    <limit lower="-3.14" upper="3.14" effort="9" velocity="3.14" />
  </joint>

  <link name="link_6">
    <inertial>
      <origin xyz="-1.6619E-15 3.4979E-14 0.048234" rpy="0 0 0" />
      <mass value="0.034232" />
      <inertia ixx="2.1585E-05" ixy="1.7922E-13" ixz="-1.8119E-20" iyy="2.3017E-05" iyz="3.404E-20" izz="2.6117E-05" />
    </inertial>
    <visual>
      <origin xyz="0 0 0" rpy="0 0 0" />
      <geometry>
        <mesh filename="package://rm_description/meshes/link_6.STL" />
      </geometry>
      <material name="">
        <color rgba="0.79216 0.81961 0.93333 1" />
      </material>
    </visual>
    <collision>
      <origin xyz="0 0 0" rpy="0 0 0" />
      <geometry>
        <mesh filename="package://rm_description/meshes/link_6.STL" />
      </geometry>
    </collision>
  </link>

  <joint name="Joint_6" type="revolute">
    <origin xyz="0 0 0" rpy="-1.5708 0 0" />
    <parent link="link_5" />
    <child link="link_6" />
    <axis xyz="0 0 1" />
    <limit lower="-3.14" upper="3.14" effort="3" velocity="3.14" />
  </joint>

  <!-- ==================== 夹爪部分 (原 gripper.urdf，重命名 base_link 为 gripper_base_link) ==================== -->
  <link name="gripper_base_link">
    <inertial>
      <origin xyz="7.2736E-05 2.8921E-05 0.041036" rpy="0 0 0" />
      <mass value="0.10913" />
      <inertia ixx="2.7236E-05" ixy="6.6965E-10" ixz="-2.4035E-08" iyy="0.00021318" iyz="-4.3193E-09" izz="0.0002363" />
    </inertial>
    <visual>
      <origin xyz="0 0 0" rpy="0 0 0" />
      <geometry>
        <mesh filename="package://rm_description/meshes/gripper_base_link.STL" />
      </geometry>
      <material name="">
        <color rgba="0.79216 0.81961 0.93333 1" />
      </material>
    </visual>
    <collision>
      <origin xyz="0 0 0" rpy="0 0 0" />
      <geometry>
        <mesh filename="package://rm_description/meshes/gripper_base_link.STL" />
      </geometry>
    </collision>
  </link>

  <link name="link_gripper_left">
    <inertial>
      <origin xyz="-0.024393 0.0010842 -0.071878" rpy="0 0 0" />
      <mass value="0.074092" />
      <inertia ixx="1.6574E-05" ixy="-1.1348E-08" ixz="-1.8449E-06" iyy="3.671E-05" iyz="-4.7593E-08" izz="2.7477E-05" />
    </inertial>
    <visual>
      <origin xyz="0 0 0" rpy="0 0 0" />
      <geometry>
        <mesh filename="package://rm_description/meshes/link_gripper_left.STL" />
      </geometry>
      <material name="">
        <color rgba="0.79216 0.81961 0.93333 1" />
      </material>
    </visual>
    <collision>
      <origin xyz="0 0 0" rpy="0 0 0" />
      <geometry>
        <mesh filename="package://rm_description/meshes/link_gripper_left.STL" />
      </geometry>
    </collision>
  </link>

  <joint name="joint_gripper_left" type="prismatic">
    <origin xyz="0 0 0.114" rpy="3.1416 -1.5708 0" />
    <parent link="gripper_base_link" />
    <child link="link_gripper_left" />
    <axis xyz="0.078458 0 -0.99692" />
    <limit lower="-0.03" upper="0.03" effort="0" velocity="0" />
  </joint>

  <link name="link_gripper_right">
    <inertial>
      <origin xyz="-0.023454 -0.0010842 0.071878" rpy="0 0 0" />
      <mass value="0.074092" />
      <inertia ixx="1.6574E-05" ixy="1.1348E-08" ixz="1.8449E-06" iyy="3.671E-05" iyz="-4.7593E-08" izz="2.7477E-05" />
    </inertial>
    <visual>
      <origin xyz="0 0 0" rpy="0 0 0" />
      <geometry>
        <mesh filename="package://rm_description/meshes/link_gripper_right.STL" />
      </geometry>
      <material name="">
        <color rgba="0.79216 0.81961 0.93333 1" />
      </material>
    </visual>
    <collision>
      <origin xyz="0 0 0" rpy="0 0 0" />
      <geometry>
        <mesh filename="package://rm_description/meshes/link_gripper_right.STL" />
      </geometry>
    </collision>
  </link>

  <joint name="joint_gripper_right" type="prismatic">
    <origin xyz="0 0 0.114" rpy="3.1416 -1.5708 0" />
    <parent link="gripper_base_link" />
    <child link="link_gripper_right" />
    <axis xyz="0.078458 0 -0.99692" />
    <limit lower="-0.03" upper="0.03" effort="0" velocity="0" />
    <mimic joint="joint_gripper_left" />
    <multiplier value="-1.0" />
  </joint>


  <joint name="joint_gripper_attach" type="fixed">
    <origin xyz="0 0 0" rpy="0 0 1.57" />
    <parent link="link_6" />
    <child link="gripper_base_link" />
  </joint>

</robot>